Workbook
Name Slicer_Buy___Sell: #N/A
Name Slicer_Market: #N/A
Name Slicer_Win_Loss: #N/A
Name Slicer_Years__Date: #N/A

Sheet  Log
A1: TRADE SUMMARY
A2: No of Records | B2: =COUNT(A10:A43) -> 34
A3: Total Wins | B3: =COUNTIF(I10:I43, "PROFIT") -> 28
A4: Total Losses | B4: =COUNTIF(I10:I43, "LOSS") -> 6
A5: Win % | B5: =COUNTIF(I10:I43,"PROFIT") / COUNTA(I10:I43)* 100 -> 82.352941
A8: Date | B8: Market | C8: Pair | D8: buy / sell | E8: Entry Price | F8: Exit Price | G8: Stop Loss | H8: Take Profit | I8: Result | J8: points/pips gained
A10: 45814 | B10: NSE | C10: HDFCBANK | D10: BUY | E10: 1981.4 | F10: 1996.6 | G10: 1917.3 | H10: 1996.6 | I10: PROFIT | J10: =ABS(E10-F10) -> 15.2
A11: 45793 | B11: NSE | C11: BHEL | D11: BUY | E11: 259.75 | F11: 266.45 | G11: 233.15 | H11: 266.45 | I11: PROFIT | J11: =ABS(E11-F11) -> 6.7
A12: 45821 | B12: NSE | C12: KVB | D12: BUY | E12: 247.8 | F12: 252.15 | G12: 227.06 | H12: 252.15 | I12: PROFIT | J12: =ABS(E12-F12) -> 4.35
A13: 45819 | B13: NSE | C13: BPCL | D13: BUY | E13: 327.5 | F13: 306.25 | G13: 306.25 | H13: 341.15 | I13: LOSS | J13: =ABS(E13-F13) -> 21.25
A14: 45810 | B14: NSE | C14: UNIONBANK | D14: BUY | E14: 153.07 | F14: 138.98 | G14: 138.98 | H14: 160.8 | I14: LOSS | J14: =ABS(E14-F14) -> 14.09
A15: 45831 | B15: NSE | C15: BEL | D15: BUY | E15: 410.95 | F15: 425.13 | G15: 392.3 | H15: 425.13 | I15: PROFIT | J15: =ABS(E15-F15) -> 14.18
A16: 45832 | B16: NSE | C16: HDFCBANK | D16: BUY | E16: 2004.2 | F16: 2022.15 | G16: 1902.9 | H16: 2022.15 | I16: PROFIT | J16: =ABS(E16-F16) -> 17.95
A17: 45833 | B17: NSE | C17: JIOFIN | D17: BUY | E17: 313.25 | F17: 332.2 | G17: 278.5 | H17: 332.2 | I17: PROFIT | J17: =ABS(E17-F17) -> 18.95
A18: 45835 | B18: NSE | C18: KVB | D18: BUY | E18: 256.15 | F18: 262.25 | G18: 245.14 | H18: 262.25 | I18: PROFIT | J18: =ABS(E18-F18) -> 6.1
A19: 45664 | B19: NSE | C19: RBL BANK | D19: BUY | E19: 252.7 | F19: 259.35 | G19: 228.63 | H19: 259.35 | I19: PROFIT | J19: =ABS(E19-F19) -> 6.65
A20: 45027 | B20: FOREX | C20: XAUUSD | D20: BUY | E20: 3189.61 | F20: 3296.744 | G20: 2945.01 | H20: 3296.744 | I20: PROFIT | J20: =IF(OR(ISNUMBER(SEARCH("JPY", C20)), ISNUMBER(SEARCH("XAU", C20))), IF(D20="Buy", (F20 - E20) * 100, (E20 - F20) * 100), IF(OR(ISNUMBER(SEARCH("BTC", C20)), ISNUMBER(SEARCH("ETH", C20))), IF(D20="Buy", F20 - E20, E20 - F20), IF(D20="Buy", (F20 - E20) * 10000, (E20 - F20) * 10000))) -> 10713.4
A21: 45031 | B21: FOREX | C21: GBPUSD | D21: BUY | E21: 1.3208 | F21: 1.32488 | G21: 1.302 | H21: 1.32488 | I21: PROFIT | J21: =IF(OR(ISNUMBER(SEARCH("JPY", C21)), ISNUMBER(SEARCH("XAU", C21))), IF(D21="Buy", (F21 - E21) * 100, (E21 - F21) * 100), IF(OR(ISNUMBER(SEARCH("BTC", C21)), ISNUMBER(SEARCH("ETH", C21))), IF(D21="Buy", F21 - E21, E21 - F21), IF(D21="Buy", (F21 - E21) * 10000, (E21 - F21) * 10000))) -> 40.8
A22: 45032 | B22: FOREX | C22: XAUUSD | D22: BUY | E22: 3274.15 | F22: 3333.51 | G22: 318.82 | H22: 3333.51 | I22: PROFIT | J22: =IF(OR(ISNUMBER(SEARCH("JPY", C22)), ISNUMBER(SEARCH("XAU", C22))), IF(D22="Buy", (F22 - E22) * 100, (E22 - F22) * 100), IF(OR(ISNUMBER(SEARCH("BTC", C22)), ISNUMBER(SEARCH("ETH", C22))), IF(D22="Buy", F22 - E22, E22 - F22), IF(D22="Buy", (F22 - E22) * 10000, (E22 - F22) * 10000))) -> 5936
A23: 45037 | B23: FOREX | C23: XAUUSD | D23: BUY | E23: 3418.05 | F23: 3422.75 | G23: 3269.55 | H23: 3422.75 | I23: PROFIT | J23: =IF(OR(ISNUMBER(SEARCH("JPY", C23)), ISNUMBER(SEARCH("XAU", C23))), IF(D23="Buy", (F23 - E23) * 100, (E23 - F23) * 100), IF(OR(ISNUMBER(SEARCH("BTC", C23)), ISNUMBER(SEARCH("ETH", C23))), IF(D23="Buy", F23 - E23, E23 - F23), IF(D23="Buy", (F23 - E23) * 10000, (E23 - F23) * 10000))) -> 470
A24: 45100 | B24: FOREX | C24: EURJPY | D24: BUY | E24: 168.207 | F24: 168.774 | G24: 165.999 | H24: 168.774 | I24: PROFIT | J24: =IF(OR(ISNUMBER(SEARCH("JPY", C24)), ISNUMBER(SEARCH("XAU", C24))), IF(D24="Buy", (F24 - E24) * 100, (E24 - F24) * 100), IF(OR(ISNUMBER(SEARCH("BTC", C24)), ISNUMBER(SEARCH("ETH", C24))), IF(D24="Buy", F24 - E24, E24 - F24), IF(D24="Buy", (F24 - E24) * 10000, (E24 - F24) * 10000))) -> 56.7
A25: 45100 | B25: FOREX | C25: EURJPY | D25: BUY | E25: 169.446 | F25: 168.749 | G25: 167.902 | H25: 170.5 | I25: LOSS | J25: =IF(OR(ISNUMBER(SEARCH("JPY", C25)), ISNUMBER(SEARCH("XAU", C25))), IF(D25="Buy", (F25 - E25) * 100, (E25 - F25) * 100), IF(OR(ISNUMBER(SEARCH("BTC", C25)), ISNUMBER(SEARCH("ETH", C25))), IF(D25="Buy", F25 - E25, E25 - F25), IF(D25="Buy", (F25 - E25) * 10000, (E25 - F25) * 10000))) -> -69.7
A26: 45110 | B26: FOREX | C26: EURJPY | D26: BUY | E26: 170.01 | F26: 170.595 | G26: 168.935 | H26: 170.595 | I26: PROFIT | J26: =IF(OR(ISNUMBER(SEARCH("JPY", C26)), ISNUMBER(SEARCH("XAU", C26))), IF(D26="Buy", (F26 - E26) * 100, (E26 - F26) * 100), IF(OR(ISNUMBER(SEARCH("BTC", C26)), ISNUMBER(SEARCH("ETH", C26))), IF(D26="Buy", F26 - E26, E26 - F26), IF(D26="Buy", (F26 - E26) * 10000, (E26 - F26) * 10000))) -> 58.5
A27: 45123 | B27: FOREX | C27: EURUSD | D27: SELL | E27: 1.1569 | F27: 1.17149 | G27: -- | H27: 1.15042 | I27: LOSS | J27: =IF(OR(ISNUMBER(SEARCH("JPY", C27)), ISNUMBER(SEARCH("XAU", C27))), IF(D27="Buy", (F27 - E27) * 100, (E27 - F27) * 100), IF(OR(ISNUMBER(SEARCH("BTC", C27)), ISNUMBER(SEARCH("ETH", C27))), IF(D27="Buy", F27 - E27, E27 - F27), IF(D27="Buy", (F27 - E27) * 10000, (E27 - F27) * 10000))) -> -145.9
A28: 45594 | B28: CRYPTO | C28: BTCUSD | D28: BUY | E28: 70283 | F28: 71806 | G28: 65193 | H28: 71806 | I28: PROFIT | J28: =IF(OR(ISNUMBER(SEARCH("JPY", C28)), ISNUMBER(SEARCH("XAU", C28))), IF(D28="Buy", (F28 - E28) * 100, (E28 - F28) * 100), IF(OR(ISNUMBER(SEARCH("BTC", C28)), ISNUMBER(SEARCH("ETH", C28))), IF(D28="Buy", F28 - E28, E28 - F28), IF(D28="Buy", (F28 - E28) * 10000, (E28 - F28) * 10000))) -> 1523
A29: 45350 | B29: CRYPTO | C29: BTCUSD | D29: SELL | E29: 79847 | F29: 87333 | G29: 87333 | H29: 77019 | I29: LOSS | J29: =IF(OR(ISNUMBER(SEARCH("JPY", C29)), ISNUMBER(SEARCH("XAU", C29))), IF(D29="Buy", (F29 - E29) * 100, (E29 - F29) * 100), IF(OR(ISNUMBER(SEARCH("BTC", C29)), ISNUMBER(SEARCH("ETH", C29))), IF(D29="Buy", F29 - E29, E29 - F29), IF(D29="Buy", (F29 - E29) * 10000, (E29 - F29) * 10000))) -> -7486
A30: 45433 | B30: CRYPTO | C30: BTCUSD | D30: BUY | E30: 109853 | F30: 111607 | G30: 10623 | H30: 11193 | I30: PROFIT | J30: =IF(OR(ISNUMBER(SEARCH("JPY", C30)), ISNUMBER(SEARCH("XAU", C30))), IF(D30="Buy", (F30 - E30) * 100, (E30 - F30) * 100), IF(OR(ISNUMBER(SEARCH("BTC", C30)), ISNUMBER(SEARCH("ETH", C30))), IF(D30="Buy", F30 - E30, E30 - F30), IF(D30="Buy", (F30 - E30) * 10000, (E30 - F30) * 10000))) -> 1754
A31: 45831 | B31: CRYPTO | C31: BTCUSD | D31: SELL | E31: 99607.62 | F31: 102319 | G31: 102319 | H31: 97846 | I31: LOSS | J31: =IF(OR(ISNUMBER(SEARCH("JPY", C31)), ISNUMBER(SEARCH("XAU", C31))), IF(D31="Buy", (F31 - E31) * 100, (E31 - F31) * 100), IF(OR(ISNUMBER(SEARCH("BTC", C31)), ISNUMBER(SEARCH("ETH", C31))), IF(D31="Buy", F31 - E31, E31 - F31), IF(D31="Buy", (F31 - E31) * 10000, (E31 - F31) * 10000))) -> -2711.38
A32: 45847 | B32: CRYPTO | C32: ETHUSD | D32: BUY | E32: 2699.99 | F32: 2746.37 | G32: -- | H32: 2746.37 | I32: PROFIT | J32: =IF(OR(ISNUMBER(SEARCH("JPY", C32)), ISNUMBER(SEARCH("XAU", C32))), IF(D32="Buy", (F32 - E32) * 100, (E32 - F32) * 100), IF(OR(ISNUMBER(SEARCH("BTC", C32)), ISNUMBER(SEARCH("ETH", C32))), IF(D32="Buy", F32 - E32, E32 - F32), IF(D32="Buy", (F32 - E32) * 10000, (E32 - F32) * 10000))) -> 46.38
A33: 45848 | B33: CRYPTO | C33: ETHUSD | D33: BUY | E33: 2964.78 | F33: 3041.69 | G33: -- | H33: 3041.69 | I33: PROFIT | J33: =IF(OR(ISNUMBER(SEARCH("JPY", C33)), ISNUMBER(SEARCH("XAU", C33))), IF(D33="Buy", (F33 - E33) * 100, (E33 - F33) * 100), IF(OR(ISNUMBER(SEARCH("BTC", C33)), ISNUMBER(SEARCH("ETH", C33))), IF(D33="Buy", F33 - E33, E33 - F33), IF(D33="Buy", (F33 - E33) * 10000, (E33 - F33) * 10000))) -> 76.91
A34: 45848 | B34: CRYPTO | C34: BTCUSD | D34: BUY | E34: 112412 | F34: 113478 | G34: 105000 | H34: 113478 | I34: PROFIT | J34: =IF(OR(ISNUMBER(SEARCH("JPY", C34)), ISNUMBER(SEARCH("XAU", C34))), IF(D34="Buy", (F34 - E34) * 100, (E34 - F34) * 100), IF(OR(ISNUMBER(SEARCH("BTC", C34)), ISNUMBER(SEARCH("ETH", C34))), IF(D34="Buy", F34 - E34, E34 - F34), IF(D34="Buy", (F34 - E34) * 10000, (E34 - F34) * 10000))) -> 1066
A35: 45848 | B35: CRYPTO | C35: BTCUSD | D35: BUY | E35: 112412 | F35: 113478 | G35: 108168 | H35: 113478 | I35: PROFIT | J35: =IF(OR(ISNUMBER(SEARCH("JPY", C35)), ISNUMBER(SEARCH("XAU", C35))), IF(D35="Buy", (F35 - E35) * 100, (E35 - F35) * 100), IF(OR(ISNUMBER(SEARCH("BTC", C35)), ISNUMBER(SEARCH("ETH", C35))), IF(D35="Buy", F35 - E35, E35 - F35), IF(D35="Buy", (F35 - E35) * 10000, (E35 - F35) * 10000))) -> 1066
A36: 45850 | B36: CRYPTO | C36: BTCUSD | D36: BUY | E36: 118076.8 | F36: 122118.99 | G36: -- | H36: 122118.99 | I36: PROFIT | J36: =IF(OR(ISNUMBER(SEARCH("JPY", C36)), ISNUMBER(SEARCH("XAU", C36))), IF(D36="Buy", (F36 - E36) * 100, (E36 - F36) * 100), IF(OR(ISNUMBER(SEARCH("BTC", C36)), ISNUMBER(SEARCH("ETH", C36))), IF(D36="Buy", F36 - E36, E36 - F36), IF(D36="Buy", (F36 - E36) * 10000, (E36 - F36) * 10000))) -> 4042.19
A37: 45851 | B37: CRYPTO | C37: BTCUSD | D37: BUY | E37: 118691.22 | F37: 122066.72 | G37: -- | H37: 122066.72 | I37: PROFIT | J37: =IF(OR(ISNUMBER(SEARCH("JPY", C37)), ISNUMBER(SEARCH("XAU", C37))), IF(D37="Buy", (F37 - E37) * 100, (E37 - F37) * 100), IF(OR(ISNUMBER(SEARCH("BTC", C37)), ISNUMBER(SEARCH("ETH", C37))), IF(D37="Buy", F37 - E37, E37 - F37), IF(D37="Buy", (F37 - E37) * 10000, (E37 - F37) * 10000))) -> 3375.5
A38: 45851 | B38: CRYPTO | C38: BTCUSD | D38: BUY | E38: 118823.68 | F38: 122066.72 | G38: -- | H38: 122066.72 | I38: PROFIT | J38: =IF(OR(ISNUMBER(SEARCH("JPY", C38)), ISNUMBER(SEARCH("XAU", C38))), IF(D38="Buy", (F38 - E38) * 100, (E38 - F38) * 100), IF(OR(ISNUMBER(SEARCH("BTC", C38)), ISNUMBER(SEARCH("ETH", C38))), IF(D38="Buy", F38 - E38, E38 - F38), IF(D38="Buy", (F38 - E38) * 10000, (E38 - F38) * 10000))) -> 3243.04
A39: 45851 | B39: CRYPTO | C39: BTCUSD | D39: BUY | E39: 118703.25 | F39: 122066.72 | G39: -- | H39: 122066.72 | I39: PROFIT | J39: =IF(OR(ISNUMBER(SEARCH("JPY", C39)), ISNUMBER(SEARCH("XAU", C39))), IF(D39="Buy", (F39 - E39) * 100, (E39 - F39) * 100), IF(OR(ISNUMBER(SEARCH("BTC", C39)), ISNUMBER(SEARCH("ETH", C39))), IF(D39="Buy", F39 - E39, E39 - F39), IF(D39="Buy", (F39 - E39) * 10000, (E39 - F39) * 10000))) -> 3363.47
A40: 45852 | B40: CRYPTO | C40: BTCUSD | D40: BUY | E40: 119689.63 | F40: 122000 | G40: -- | H40: 122000 | I40: PROFIT | J40: =IF(OR(ISNUMBER(SEARCH("JPY", C40)), ISNUMBER(SEARCH("XAU", C40))), IF(D40="Buy", (F40 - E40) * 100, (E40 - F40) * 100), IF(OR(ISNUMBER(SEARCH("BTC", C40)), ISNUMBER(SEARCH("ETH", C40))), IF(D40="Buy", F40 - E40, E40 - F40), IF(D40="Buy", (F40 - E40) * 10000, (E40 - F40) * 10000))) -> 2310.37
A41: 45853 | B41: CRYPTO | C41: ETHUSD | D41: BUY | E41: 2982.26 | F41: 3225.57 | G41: -- | H41: 3225.57 | I41: PROFIT | J41: =IF(OR(ISNUMBER(SEARCH("JPY", C41)), ISNUMBER(SEARCH("XAU", C41))), IF(D41="Buy", (F41 - E41) * 100, (E41 - F41) * 100), IF(OR(ISNUMBER(SEARCH("BTC", C41)), ISNUMBER(SEARCH("ETH", C41))), IF(D41="Buy", F41 - E41, E41 - F41), IF(D41="Buy", (F41 - E41) * 10000, (E41 - F41) * 10000))) -> 243.31
A42: 45854 | B42: CRYPTO | C42: ETHUSD | D42: BUY | E42: 3197.7 | F42: 3225.57 | G42: -- | H42: 3225.57 | I42: PROFIT | J42: =IF(OR(ISNUMBER(SEARCH("JPY", C42)), ISNUMBER(SEARCH("XAU", C42))), IF(D42="Buy", (F42 - E42) * 100, (E42 - F42) * 100), IF(OR(ISNUMBER(SEARCH("BTC", C42)), ISNUMBER(SEARCH("ETH", C42))), IF(D42="Buy", F42 - E42, E42 - F42), IF(D42="Buy", (F42 - E42) * 10000, (E42 - F42) * 10000))) -> 27.87
A43: 45854 | B43: CRYPTO | C43: ETHUSD | D43: BUY | E43: 3185.5 | F43: 3225.57 | G43: -- | H43: 3225.57 | I43: PROFIT | J43: =IF(OR(ISNUMBER(SEARCH("JPY", C43)), ISNUMBER(SEARCH("XAU", C43))), IF(D43="Buy", (F43 - E43) * 100, (E43 - F43) * 100), IF(OR(ISNUMBER(SEARCH("BTC", C43)), ISNUMBER(SEARCH("ETH", C43))), IF(D43="Buy", F43 - E43, E43 - F43), IF(D43="Buy", (F43 - E43) * 10000, (E43 - F43) * 10000))) -> 40.07
...

Sheet Profit Calculation
A4: Date | B4: Market | C4: Pair | D4: Buy / Sell | E4: Qunatity | F4: points/pips gained | G4: Win/Loss | H4: Profit | K4: Total Profit
A5: 45027 | B5: FOREX | C5: XAUUSD | D5: BUY | E5: 0.02 | F5: =IF(OR(ISNUMBER(SEARCH("JPY", ' Log'!C20)), ISNUMBER(SEARCH("XAU",' Log'!C20))), IF(' Log'!D20="Buy", (' Log'!F20 -' Log'!E20) * 100, (' Log'!E20 - ' Log'!F20) * 100), IF(OR(ISNUMBER(SEARCH("BTC", ' Log'!C20)), ISNUMBER(SEARCH("ETH", ' Log'!C20))), IF(' Log'!D20="Buy", ' Log'!F20 - ' Log'!E20, ' Log'!E20 - ' Log'!F20), IF(' Log'!D20="Buy", (' Log'!F20 - ' Log'!E20) * 10000, (' Log'!E20 - ' Log'!F20) * 10000))) -> 10713.4 | G5: =IF(H5>0, "Win", "Loss") -> Win | H5: =IF(OR(ISNUMBER(SEARCH("BTC", 'Profit Calculation'!C5)), ISNUMBER(SEARCH("ETH", 'Profit Calculation'!C5))), ' Log'!J20 * 'Profit Calculation'!E5, IF(ISNUMBER(SEARCH("XAU",'Profit Calculation'!C5)), ' Log'!J20 *'Profit Calculation'!E5, ' Log'!J20 *10* 'Profit Calculation'!E5)) -> 214.268 | K5: =SUM(H5:H28) -> 6385.734
A6: 45031 | B6: FOREX | C6: GBPUSD | D6: BUY | E6: 0.03 | F6: =IF(OR(ISNUMBER(SEARCH("JPY", ' Log'!C21)), ISNUMBER(SEARCH("XAU",' Log'!C21))), IF(' Log'!D21="Buy", (' Log'!F21 -' Log'!E21) * 100, (' Log'!E21 - ' Log'!F21) * 100), IF(OR(ISNUMBER(SEARCH("BTC", ' Log'!C21)), ISNUMBER(SEARCH("ETH", ' Log'!C21))), IF(' Log'!D21="Buy", ' Log'!F21 - ' Log'!E21, ' Log'!E21 - ' Log'!F21), IF(' Log'!D21="Buy", (' Log'!F21 - ' Log'!E21) * 10000, (' Log'!E21 - ' Log'!F21) * 10000))) -> 40.8 | G6: =IF(H6>0, "Win", "Loss") -> Win | H6: =IF(OR(ISNUMBER(SEARCH("BTC", 'Profit Calculation'!C6)), ISNUMBER(SEARCH("ETH", 'Profit Calculation'!C6))), ' Log'!J21 * 'Profit Calculation'!E6, IF(ISNUMBER(SEARCH("XAU",'Profit Calculation'!C6)), ' Log'!J21 *'Profit Calculation'!E6, ' Log'!J21 *10* 'Profit Calculation'!E6)) -> 12.24 | K6: Total Trades
A7: 45032 | B7: FOREX | C7: XAUUSD | D7: BUY | E7: 0.02 | F7: =IF(OR(ISNUMBER(SEARCH("JPY", ' Log'!C22)), ISNUMBER(SEARCH("XAU",' Log'!C22))), IF(' Log'!D22="Buy", (' Log'!F22 -' Log'!E22) * 100, (' Log'!E22 - ' Log'!F22) * 100), IF(OR(ISNUMBER(SEARCH("BTC", ' Log'!C22)), ISNUMBER(SEARCH("ETH", ' Log'!C22))), IF(' Log'!D22="Buy", ' Log'!F22 - ' Log'!E22, ' Log'!E22 - ' Log'!F22), IF(' Log'!D22="Buy", (' Log'!F22 - ' Log'!E22) * 10000, (' Log'!E22 - ' Log'!F22) * 10000))) -> 5936 | G7: =IF(H7>0, "Win", "Loss") -> Win | H7: =IF(OR(ISNUMBER(SEARCH("BTC", 'Profit Calculation'!C7)), ISNUMBER(SEARCH("ETH", 'Profit Calculation'!C7))), ' Log'!J22 * 'Profit Calculation'!E7, IF(ISNUMBER(SEARCH("XAU",'Profit Calculation'!C7)), ' Log'!J22 *'Profit Calculation'!E7, ' Log'!J22 *10* 'Profit Calculation'!E7)) -> 118.72 | K7: =COUNT(H5:H28) -> 24
A8: 45037 | B8: FOREX | C8: XAUUSD | D8: BUY | E8: 0.01 | F8: =IF(OR(ISNUMBER(SEARCH("JPY", ' Log'!C23)), ISNUMBER(SEARCH("XAU",' Log'!C23))), IF(' Log'!D23="Buy", (' Log'!F23 -' Log'!E23) * 100, (' Log'!E23 - ' Log'!F23) * 100), IF(OR(ISNUMBER(SEARCH("BTC", ' Log'!C23)), ISNUMBER(SEARCH("ETH", ' Log'!C23))), IF(' Log'!D23="Buy", ' Log'!F23 - ' Log'!E23, ' Log'!E23 - ' Log'!F23), IF(' Log'!D23="Buy", (' Log'!F23 - ' Log'!E23) * 10000, (' Log'!E23 - ' Log'!F23) * 10000))) -> 470 | G8: =IF(H8>0, "Win", "Loss") -> Win | H8: =IF(OR(ISNUMBER(SEARCH("BTC", 'Profit Calculation'!C8)), ISNUMBER(SEARCH("ETH", 'Profit Calculation'!C8))), ' Log'!J23 * 'Profit Calculation'!E8, IF(ISNUMBER(SEARCH("XAU",'Profit Calculation'!C8)), ' Log'!J23 *'Profit Calculation'!E8, ' Log'!J23 *10* 'Profit Calculation'!E8)) -> 4.7 | K8: Win %
A9: 45100 | B9: FOREX | C9: EURJPY | D9: BUY | E9: 0.02 | F9: =IF(OR(ISNUMBER(SEARCH("JPY", ' Log'!C24)), ISNUMBER(SEARCH("XAU",' Log'!C24))), IF(' Log'!D24="Buy", (' Log'!F24 -' Log'!E24) * 100, (' Log'!E24 - ' Log'!F24) * 100), IF(OR(ISNUMBER(SEARCH("BTC", ' Log'!C24)), ISNUMBER(SEARCH("ETH", ' Log'!C24))), IF(' Log'!D24="Buy", ' Log'!F24 - ' Log'!E24, ' Log'!E24 - ' Log'!F24), IF(' Log'!D24="Buy", (' Log'!F24 - ' Log'!E24) * 10000, (' Log'!E24 - ' Log'!F24) * 10000))) -> 56.7 | G9: =IF(H9>0, "Win", "Loss") -> Win | H9: =IF(OR(ISNUMBER(SEARCH("BTC", 'Profit Calculation'!C9)), ISNUMBER(SEARCH("ETH", 'Profit Calculation'!C9))), ' Log'!J24 * 'Profit Calculation'!E9, IF(ISNUMBER(SEARCH("XAU",'Profit Calculation'!C9)), ' Log'!J24 *'Profit Calculation'!E9, ' Log'!J24 *10* 'Profit Calculation'!E9)) -> 11.34 | K9: =COUNTIF(H3:H28,">0")/K7 -> 0.83333333
A10: 45100 | B10: FOREX | C10: EURJPY | D10: BUY | E10: 0.07 | F10: =IF(OR(ISNUMBER(SEARCH("JPY", ' Log'!C25)), ISNUMBER(SEARCH("XAU",' Log'!C25))), IF(' Log'!D25="Buy", (' Log'!F25 -' Log'!E25) * 100, (' Log'!E25 - ' Log'!F25) * 100), IF(OR(ISNUMBER(SEARCH("BTC", ' Log'!C25)), ISNUMBER(SEARCH("ETH", ' Log'!C25))), IF(' Log'!D25="Buy", ' Log'!F25 - ' Log'!E25, ' Log'!E25 - ' Log'!F25), IF(' Log'!D25="Buy", (' Log'!F25 - ' Log'!E25) * 10000, (' Log'!E25 - ' Log'!F25) * 10000))) -> -69.7 | G10: =IF(H10>0, "Win", "Loss") -> Loss | H10: =IF(OR(ISNUMBER(SEARCH("BTC", 'Profit Calculation'!C10)), ISNUMBER(SEARCH("ETH", 'Profit Calculation'!C10))), ' Log'!J25 * 'Profit Calculation'!E10, IF(ISNUMBER(SEARCH("XAU",'Profit Calculation'!C10)), ' Log'!J25 *'Profit Calculation'!E10, ' Log'!J25 *10* 'Profit Calculation'!E10)) -> -48.79
A11: 45110 | B11: FOREX | C11: EURJPY | D11: BUY | E11: 0.1 | F11: =IF(OR(ISNUMBER(SEARCH("JPY", ' Log'!C26)), ISNUMBER(SEARCH("XAU",' Log'!C26))), IF(' Log'!D26="Buy", (' Log'!F26 -' Log'!E26) * 100, (' Log'!E26 - ' Log'!F26) * 100), IF(OR(ISNUMBER(SEARCH("BTC", ' Log'!C26)), ISNUMBER(SEARCH("ETH", ' Log'!C26))), IF(' Log'!D26="Buy", ' Log'!F26 - ' Log'!E26, ' Log'!E26 - ' Log'!F26), IF(' Log'!D26="Buy", (' Log'!F26 - ' Log'!E26) * 10000, (' Log'!E26 - ' Log'!F26) * 10000))) -> 58.5 | G11: =IF(H11>0, "Win", "Loss") -> Win | H11: =IF(OR(ISNUMBER(SEARCH("BTC", 'Profit Calculation'!C11)), ISNUMBER(SEARCH("ETH", 'Profit Calculation'!C11))), ' Log'!J26 * 'Profit Calculation'!E11, IF(ISNUMBER(SEARCH("XAU",'Profit Calculation'!C11)), ' Log'!J26 *'Profit Calculation'!E11, ' Log'!J26 *10* 'Profit Calculation'!E11)) -> 58.5
A12: 45123 | B12: FOREX | C12: EURUSD | D12: BUY | E12: 0.1 | F12: =IF(OR(ISNUMBER(SEARCH("JPY", ' Log'!C27)), ISNUMBER(SEARCH("XAU",' Log'!C27))), IF(' Log'!D27="Buy", (' Log'!F27 -' Log'!E27) * 100, (' Log'!E27 - ' Log'!F27) * 100), IF(OR(ISNUMBER(SEARCH("BTC", ' Log'!C27)), ISNUMBER(SEARCH("ETH", ' Log'!C27))), IF(' Log'!D27="Buy", ' Log'!F27 - ' Log'!E27, ' Log'!E27 - ' Log'!F27), IF(' Log'!D27="Buy", (' Log'!F27 - ' Log'!E27) * 10000, (' Log'!E27 - ' Log'!F27) * 10000))) -> -145.9 | G12: =IF(H12>0, "Win", "Loss") -> Loss | H12: =IF(OR(ISNUMBER(SEARCH("BTC", 'Profit Calculation'!C12)), ISNUMBER(SEARCH("ETH", 'Profit Calculation'!C12))), ' Log'!J27 * 'Profit Calculation'!E12, IF(ISNUMBER(SEARCH("XAU",'Profit Calculation'!C12)), ' Log'!J27 *'Profit Calculation'!E12, ' Log'!J27 *10* 'Profit Calculation'!E12)) -> -145.9
A13: 45594 | B13: CRYPTO | C13: BTCUSD | D13: BUY | E13: 0.01 | F13: =IF(OR(ISNUMBER(SEARCH("JPY", ' Log'!C28)), ISNUMBER(SEARCH("XAU",' Log'!C28))), IF(' Log'!D28="Buy", (' Log'!F28 -' Log'!E28) * 100, (' Log'!E28 - ' Log'!F28) * 100), IF(OR(ISNUMBER(SEARCH("BTC", ' Log'!C28)), ISNUMBER(SEARCH("ETH", ' Log'!C28))), IF(' Log'!D28="Buy", ' Log'!F28 - ' Log'!E28, ' Log'!E28 - ' Log'!F28), IF(' Log'!D28="Buy", (' Log'!F28 - ' Log'!E28) * 10000, (' Log'!E28 - ' Log'!F28) * 10000))) -> 1523 | G13: =IF(H13>0, "Win", "Loss") -> Win | H13: =IF(OR(ISNUMBER(SEARCH("BTC", 'Profit Calculation'!C13)), ISNUMBER(SEARCH("ETH", 'Profit Calculation'!C13))), ' Log'!J28 * 'Profit Calculation'!E13, IF(ISNUMBER(SEARCH("XAU",'Profit Calculation'!C13)), ' Log'!J28 *'Profit Calculation'!E13, ' Log'!J28 *10* 'Profit Calculation'!E13)) -> 15.23
A14: 45350 | B14: CRYPTO | C14: BTCUSD | D14: SELL | E14: 0.01 | F14: =IF(OR(ISNUMBER(SEARCH("JPY", ' Log'!C29)), ISNUMBER(SEARCH("XAU",' Log'!C29))), IF(' Log'!D29="Buy", (' Log'!F29 -' Log'!E29) * 100, (' Log'!E29 - ' Log'!F29) * 100), IF(OR(ISNUMBER(SEARCH("BTC", ' Log'!C29)), ISNUMBER(SEARCH("ETH", ' Log'!C29))), IF(' Log'!D29="Buy", ' Log'!F29 - ' Log'!E29, ' Log'!E29 - ' Log'!F29), IF(' Log'!D29="Buy", (' Log'!F29 - ' Log'!E29) * 10000, (' Log'!E29 - ' Log'!F29) * 10000))) -> -7486 | G14: =IF(H14>0, "Win", "Loss") -> Loss | H14: =IF(OR(ISNUMBER(SEARCH("BTC", 'Profit Calculation'!C14)), ISNUMBER(SEARCH("ETH", 'Profit Calculation'!C14))), ' Log'!J29 * 'Profit Calculation'!E14, IF(ISNUMBER(SEARCH("XAU",'Profit Calculation'!C14)), ' Log'!J29 *'Profit Calculation'!E14, ' Log'!J29 *10* 'Profit Calculation'!E14)) -> -74.86
A15: 45433 | B15: CRYPTO | C15: BTCUSD | D15: BUY | E15: 0.01 | F15: =IF(OR(ISNUMBER(SEARCH("JPY", ' Log'!C30)), ISNUMBER(SEARCH("XAU",' Log'!C30))), IF(' Log'!D30="Buy", (' Log'!F30 -' Log'!E30) * 100, (' Log'!E30 - ' Log'!F30) * 100), IF(OR(ISNUMBER(SEARCH("BTC", ' Log'!C30)), ISNUMBER(SEARCH("ETH", ' Log'!C30))), IF(' Log'!D30="Buy", ' Log'!F30 - ' Log'!E30, ' Log'!E30 - ' Log'!F30), IF(' Log'!D30="Buy", (' Log'!F30 - ' Log'!E30) * 10000, (' Log'!E30 - ' Log'!F30) * 10000))) -> 1754 | G15: =IF(H15>0, "Win", "Loss") -> Win | H15: =IF(OR(ISNUMBER(SEARCH("BTC", 'Profit Calculation'!C15)), ISNUMBER(SEARCH("ETH", 'Profit Calculation'!C15))), ' Log'!J30 * 'Profit Calculation'!E15, IF(ISNUMBER(SEARCH("XAU",'Profit Calculation'!C15)), ' Log'!J30 *'Profit Calculation'!E15, ' Log'!J30 *10* 'Profit Calculation'!E15)) -> 17.54
A16: 45831 | B16: CRYPTO | C16: BTCUSD | D16: SELL | E16: 0.01 | F16: =IF(OR(ISNUMBER(SEARCH("JPY", ' Log'!C31)), ISNUMBER(SEARCH("XAU",' Log'!C31))), IF(' Log'!D31="Buy", (' Log'!F31 -' Log'!E31) * 100, (' Log'!E31 - ' Log'!F31) * 100), IF(OR(ISNUMBER(SEARCH("BTC", ' Log'!C31)), ISNUMBER(SEARCH("ETH", ' Log'!C31))), IF(' Log'!D31="Buy", ' Log'!F31 - ' Log'!E31, ' Log'!E31 - ' Log'!F31), IF(' Log'!D31="Buy", (' Log'!F31 - ' Log'!E31) * 10000, (' Log'!E31 - ' Log'!F31) * 10000))) -> -2711.38 | G16: =IF(H16>0, "Win", "Loss") -> Loss | H16: =IF(OR(ISNUMBER(SEARCH("BTC", 'Profit Calculation'!C16)), ISNUMBER(SEARCH("ETH", 'Profit Calculation'!C16))), ' Log'!J31 * 'Profit Calculation'!E16, IF(ISNUMBER(SEARCH("XAU",'Profit Calculation'!C16)), ' Log'!J31 *'Profit Calculation'!E16, ' Log'!J31 *10* 'Profit Calculation'!E16)) -> -27.1138
A17: 45847 | B17: CRYPTO | C17: ETHUSD | D17: BUY | E17: 0.1 | F17: =IF(OR(ISNUMBER(SEARCH("JPY", ' Log'!C32)), ISNUMBER(SEARCH("XAU",' Log'!C32))), IF(' Log'!D32="Buy", (' Log'!F32 -' Log'!E32) * 100, (' Log'!E32 - ' Log'!F32) * 100), IF(OR(ISNUMBER(SEARCH("BTC", ' Log'!C32)), ISNUMBER(SEARCH("ETH", ' Log'!C32))), IF(' Log'!D32="Buy", ' Log'!F32 - ' Log'!E32, ' Log'!E32 - ' Log'!F32), IF(' Log'!D32="Buy", (' Log'!F32 - ' Log'!E32) * 10000, (' Log'!E32 - ' Log'!F32) * 10000))) -> 46.38 | G17: =IF(H17>0, "Win", "Loss") -> Win | H17: =IF(OR(ISNUMBER(SEARCH("BTC", 'Profit Calculation'!C17)), ISNUMBER(SEARCH("ETH", 'Profit Calculation'!C17))), ' Log'!J32 * 'Profit Calculation'!E17, IF(ISNUMBER(SEARCH("XAU",'Profit Calculation'!C17)), ' Log'!J32 *'Profit Calculation'!E17, ' Log'!J32 *10* 'Profit Calculation'!E17)) -> 4.638
A18: 45848 | B18: CRYPTO | C18: ETHUSD | D18: BUY | E18: 0.1 | F18: =IF(OR(ISNUMBER(SEARCH("JPY", ' Log'!C33)), ISNUMBER(SEARCH("XAU",' Log'!C33))), IF(' Log'!D33="Buy", (' Log'!F33 -' Log'!E33) * 100, (' Log'!E33 - ' Log'!F33) * 100), IF(OR(ISNUMBER(SEARCH("BTC", ' Log'!C33)), ISNUMBER(SEARCH("ETH", ' Log'!C33))), IF(' Log'!D33="Buy", ' Log'!F33 - ' Log'!E33, ' Log'!E33 - ' Log'!F33), IF(' Log'!D33="Buy", (' Log'!F33 - ' Log'!E33) * 10000, (' Log'!E33 - ' Log'!F33) * 10000))) -> 76.91 | G18: =IF(H18>0, "Win", "Loss") -> Win | H18: =IF(OR(ISNUMBER(SEARCH("BTC", 'Profit Calculation'!C18)), ISNUMBER(SEARCH("ETH", 'Profit Calculation'!C18))), ' Log'!J33 * 'Profit Calculation'!E18, IF(ISNUMBER(SEARCH("XAU",'Profit Calculation'!C18)), ' Log'!J33 *'Profit Calculation'!E18, ' Log'!J33 *10* 'Profit Calculation'!E18)) -> 7.691
A19: 45848 | B19: CRYPTO | C19: BTCUSD | D19: BUY | E19: 0.01 | F19: =IF(OR(ISNUMBER(SEARCH("JPY", ' Log'!C34)), ISNUMBER(SEARCH("XAU",' Log'!C34))), IF(' Log'!D34="Buy", (' Log'!F34 -' Log'!E34) * 100, (' Log'!E34 - ' Log'!F34) * 100), IF(OR(ISNUMBER(SEARCH("BTC", ' Log'!C34)), ISNUMBER(SEARCH("ETH", ' Log'!C34))), IF(' Log'!D34="Buy", ' Log'!F34 - ' Log'!E34, ' Log'!E34 - ' Log'!F34), IF(' Log'!D34="Buy", (' Log'!F34 - ' Log'!E34) * 10000, (' Log'!E34 - ' Log'!F34) * 10000))) -> 1066 | G19: =IF(H19>0, "Win", "Loss") -> Win | H19: =IF(OR(ISNUMBER(SEARCH("BTC", 'Profit Calculation'!C19)), ISNUMBER(SEARCH("ETH", 'Profit Calculation'!C19))), ' Log'!J34 * 'Profit Calculation'!E19, IF(ISNUMBER(SEARCH("XAU",'Profit Calculation'!C19)), ' Log'!J34 *'Profit Calculation'!E19, ' Log'!J34 *10* 'Profit Calculation'!E19)) -> 10.66
A20: 45848 | B20: CRYPTO | C20: BTCUSD | D20: BUY | E20: 0.02 | F20: =IF(OR(ISNUMBER(SEARCH("JPY", ' Log'!C35)), ISNUMBER(SEARCH("XAU",' Log'!C35))), IF(' Log'!D35="Buy", (' Log'!F35 -' Log'!E35) * 100, (' Log'!E35 - ' Log'!F35) * 100), IF(OR(ISNUMBER(SEARCH("BTC", ' Log'!C35)), ISNUMBER(SEARCH("ETH", ' Log'!C35))), IF(' Log'!D35="Buy", ' Log'!F35 - ' Log'!E35, ' Log'!E35 - ' Log'!F35), IF(' Log'!D35="Buy", (' Log'!F35 - ' Log'!E35) * 10000, (' Log'!E35 - ' Log'!F35) * 10000))) -> 1066 | G20: =IF(H20>0, "Win", "Loss") -> Win | H20: =IF(OR(ISNUMBER(SEARCH("BTC", 'Profit Calculation'!C20)), ISNUMBER(SEARCH("ETH", 'Profit Calculation'!C20))), ' Log'!J35 * 'Profit Calculation'!E20, IF(ISNUMBER(SEARCH("XAU",'Profit Calculation'!C20)), ' Log'!J35 *'Profit Calculation'!E20, ' Log'!J35 *10* 'Profit Calculation'!E20)) -> 21.32
A21: 45850 | B21: CRYPTO | C21: BTCUSD | D21: BUY | E21: 0.02 | F21: =IF(OR(ISNUMBER(SEARCH("JPY", ' Log'!C36)), ISNUMBER(SEARCH("XAU",' Log'!C36))), IF(' Log'!D36="Buy", (' Log'!F36 -' Log'!E36) * 100, (' Log'!E36 - ' Log'!F36) * 100), IF(OR(ISNUMBER(SEARCH("BTC", ' Log'!C36)), ISNUMBER(SEARCH("ETH", ' Log'!C36))), IF(' Log'!D36="Buy", ' Log'!F36 - ' Log'!E36, ' Log'!E36 - ' Log'!F36), IF(' Log'!D36="Buy", (' Log'!F36 - ' Log'!E36) * 10000, (' Log'!E36 - ' Log'!F36) * 10000))) -> 4042.19 | G21: =IF(H21>0, "Win", "Loss") -> Win | H21: =IF(OR(ISNUMBER(SEARCH("BTC", 'Profit Calculation'!C21)), ISNUMBER(SEARCH("ETH", 'Profit Calculation'!C21))), ' Log'!J36 * 'Profit Calculation'!E21, IF(ISNUMBER(SEARCH("XAU",'Profit Calculation'!C21)), ' Log'!J36 *'Profit Calculation'!E21, ' Log'!J36 *10* 'Profit Calculation'!E21)) -> 80.8438
... A28: 45854 | B28: CRYPTO | C28: ETHUSD | D28: BUY | E28: 0.1 | F28: =IF(OR(ISNUMBER(SEARCH("JPY", ' Log'!C43)), ISNUMBER(SEARCH("XAU",' Log'!C43))), IF(' Log'!D43="Buy", (' Log'!F43 -' Log'!E43) * 100, (' Log'!E43 - ' Log'!F43) * 100), IF(OR(ISNUMBER(SEARCH("BTC", ' Log'!C43)), ISNUMBER(SEARCH("ETH", ' Log'!C43))), IF(' Log'!D43="Buy", ' Log'!F43 - ' Log'!E43, ' Log'!E43 - ' Log'!F43), IF(' Log'!D43="Buy", (' Log'!F43 - ' Log'!E43) * 10000, (' Log'!E43 - ' Log'!F43) * 10000))) -> 40.07 | G28: =IF(H28>0, "Win", "Loss") -> Win | H28: =IF(OR(ISNUMBER(SEARCH("BTC", 'Profit Calculation'!C28)), ISNUMBER(SEARCH("ETH", 'Profit Calculation'!C28))), ' Log'!J43 * 'Profit Calculation'!E28, IF(ISNUMBER(SEARCH("XAU",'Profit Calculation'!C28)), ' Log'!J43 *'Profit Calculation'!E28, ' Log'!J43 *10* 'Profit Calculation'!E28)) -> 4.007
H29: =SUBTOTAL(109,Table2[Profit]) -> 6385.734

Sheet Pivot Table and Slicers 
H2: Pivot tables
C4: Monthly Profit Trend | G4: Profit by Pair | J4: Count of win/loss | M4: Buy vs Sell Profit
C6: Row Labels | D6: Sum of Profit | E6: Sum of points/pips gained | G6: Row Labels | H6: Sum of Profit | J6: Row Labels | K6: Count of Win/Loss | M6: Row Labels | N6: Sum of Profit
C7: 2024 | D7: -42.09 | E7: -4209 | G7: BTCUSD | H7: 5994.795 | J7: Loss | K7: 4 | M7: BUY | N7: 6487.7078
C8: Feb | D8: -74.86 | E8: -7486 | G8: EURJPY | H8: 21.05 | J8: Win | K8: 20 | M8: SELL | N8: -101.9738
C9: May | D9: 17.54 | E9: 1754 | G9: GBPUSD | H9: 12.24
C10: Oct | D10: 15.23 | E10: 1523 | G10: XAUUSD | H10: 337.688
C11: 2025 | D11: 6202.746 | E11: 16189.73 | G11: EURUSD | H11: -145.9
C12: Jun | D12: -27.1138 | E12: -2711.38 | G12: ETHUSD | H12: 165.861
C13: Jul | D13: 6229.8598 | E13: 18901.11
C14: 2023 | D14: 225.078 | E14: 17059.8
C15: Apr | D15: 349.928 | E15: 17160.2
C16: Jun | D16: -37.45 | E16: -13
C17: Jul | D17: -87.4 | E17: -87.4

Sheet Dashboard 
